<?xml version="1.0" ?>
<!-- =================================================================================== -->
<!-- |    This document was autogenerated by xacro from src/lbr_fri_ros2_stack/lbr_description/urdf/kuka_blue/kuka_blue.xacro | -->
<!-- |    EDITING THIS FILE BY HAND IS NOT RECOMMENDED                                 | -->
<!-- =================================================================================== -->
<!-- top level -->
<robot name="iiwa7">
  <!-- fixed to world, see http://classic.gazebosim.org/tutorials?tut=ros_urdf&cat=connect_ros -->
  <link name="world"/>
  <!-- joint between world and link_0 -->
  <joint name="world_joint" type="fixed">
    <parent link="world"/>
    <child link="link_0"/>
    <!-- <origin xyz="0.55 -0.4 -0.25" rpy="0 0 0.783"/> -->
    <!-- <origin xyz="0.55 -0.4 -0.35" rpy="0 0 0.783"/> -->
    <origin rpy="0 0 0" xyz="0 0 0"/>
    <!-- <origin xyz="0.6 -0.5 -0.299" rpy="0 0 0.783"/> -->
  </joint>
  <link name="link_0">
    <inertial>
      <origin rpy="0 0 0" xyz="-0.012857 0.0 0.069964"/>
      <mass value="4.855658"/>
      <inertia ixx="0.017839" ixy="0.0" ixz="0.000781" iyy="0.022294" iyz="0.0" izz="0.021334"/>
    </inertial>
    <visual>
      <origin rpy="0 0 0" xyz="0 0 0"/>
      <geometry>
        <mesh filename="package://lbr_description/meshes/iiwa7/visual/link_0.dae"/>
      </geometry>
    </visual>
    <collision>
      <origin rpy="0 0 0" xyz="0 0 0"/>
      <geometry>
        <mesh filename="package://lbr_description/meshes/iiwa7/collision/link_0.stl"/>
      </geometry>
    </collision>
  </link>
  <joint name="A1" type="revolute">
    <origin rpy="0 0 0" xyz="0.0 0.0 0.1475"/>
    <parent link="link_0"/>
    <child link="link_1"/>
    <axis xyz="0.0 0.0 1.0"/>
    <limit effort="200" lower="-2.9670597283903604" upper="2.9670597283903604" velocity="1.710422666954443"/>
    <dynamics damping="10.0" friction="0.1"/>
  </joint>
  <link name="link_1">
    <inertial>
      <origin rpy="0 0 0" xyz="0.0 -0.034819 0.123299"/>
      <mass value="3.394011"/>
      <inertia ixx="0.021383" ixy="0.0" ixz="0.0" iyy="0.020403" iyz="0.003797" izz="0.007563"/>
    </inertial>
    <visual>
      <origin rpy="0 0 0" xyz="0.0 0.0 -0.1475"/>
      <geometry>
        <mesh filename="package://lbr_description/meshes/iiwa7/visual/link_1.dae"/>
      </geometry>
    </visual>
    <collision>
      <origin rpy="0 0 0" xyz="0.0 0.0 -0.1475"/>
      <geometry>
        <mesh filename="package://lbr_description/meshes/iiwa7/collision/link_1.stl"/>
      </geometry>
    </collision>
  </link>
  <joint name="A2" type="revolute">
    <origin rpy="0 0 0" xyz="0.0 -0.0105 0.1925"/>
    <parent link="link_1"/>
    <child link="link_2"/>
    <axis xyz="0.0 1.0 0.0"/>
    <limit effort="200" lower="-2.0943951023931953" upper="2.0943951023931953" velocity="1.710422666954443"/>
    <dynamics damping="10.0" friction="0.1"/>
  </joint>
  <link name="link_2">
    <inertial>
      <origin rpy="0 0 0" xyz="0.0 0.039793 0.086944"/>
      <mass value="4.031991"/>
      <inertia ixx="0.031697" ixy="0.0" ixz="0.0" iyy="0.03008" iyz="0.005889" izz="0.009666"/>
    </inertial>
    <visual>
      <origin rpy="0 0 0" xyz="0.0 0.0105 -0.34"/>
      <geometry>
        <mesh filename="package://lbr_description/meshes/iiwa7/visual/link_2.dae"/>
      </geometry>
    </visual>
    <collision>
      <origin rpy="0 0 0" xyz="0.0 0.0105 -0.34"/>
      <geometry>
        <mesh filename="package://lbr_description/meshes/iiwa7/collision/link_2.stl"/>
      </geometry>
    </collision>
  </link>
  <joint name="A3" type="revolute">
    <origin rpy="0 0 0" xyz="0.0 0.0105 0.2075"/>
    <parent link="link_2"/>
    <child link="link_3"/>
    <axis xyz="0.0 0.0 1.0"/>
    <limit effort="200" lower="-2.9670597283903604" upper="2.9670597283903604" velocity="1.7453292519943295"/>
    <dynamics damping="10.0" friction="0.1"/>
  </joint>
  <link name="link_3">
    <inertial>
      <origin rpy="0 0 0" xyz="0.0 0.034819 0.123299"/>
      <mass value="3.394011"/>
      <inertia ixx="0.021383" ixy="0.0" ixz="0.0" iyy="0.020403" iyz="-0.003797" izz="0.007563"/>
    </inertial>
    <visual>
      <origin rpy="0 0 0" xyz="0.0 0.0 -0.5475"/>
      <geometry>
        <mesh filename="package://lbr_description/meshes/iiwa7/visual/link_3.dae"/>
      </geometry>
    </visual>
    <collision>
      <origin rpy="0 0 0" xyz="0.0 0.0 -0.5475"/>
      <geometry>
        <mesh filename="package://lbr_description/meshes/iiwa7/collision/link_3.stl"/>
      </geometry>
    </collision>
  </link>
  <joint name="A4" type="revolute">
    <origin rpy="0 0 0" xyz="0.0 0.0105 0.1925"/>
    <parent link="link_3"/>
    <child link="link_4"/>
    <axis xyz="0.0 -1.0 0.0"/>
    <limit effort="200" lower="-2.0943951023931953" upper="2.0943951023931953" velocity="2.2689280275926285"/>
    <dynamics damping="10.0" friction="0.1"/>
  </joint>
  <link name="link_4">
    <inertial>
      <origin rpy="0 0 0" xyz="0.0 -0.039793 0.086944"/>
      <mass value="4.031989"/>
      <inertia ixx="0.031695" ixy="0.0" ixz="0.0" iyy="0.030079" iyz="-0.005889" izz="0.009665"/>
    </inertial>
    <visual>
      <origin rpy="0 0 0" xyz="0.0 -0.0105 -0.74"/>
      <geometry>
        <mesh filename="package://lbr_description/meshes/iiwa7/visual/link_4.dae"/>
      </geometry>
    </visual>
    <collision>
      <origin rpy="0 0 0" xyz="0.0 -0.0105 -0.74"/>
      <geometry>
        <mesh filename="package://lbr_description/meshes/iiwa7/collision/link_4.stl"/>
      </geometry>
    </collision>
  </link>
  <joint name="A5" type="revolute">
    <origin rpy="0 0 0" xyz="0.0 -0.0105 0.2075"/>
    <parent link="link_4"/>
    <child link="link_5"/>
    <axis xyz="0.0 0.0 1.0"/>
    <limit effort="200" lower="-2.9670597283903604" upper="2.9670597283903604" velocity="2.443460952792061"/>
    <dynamics damping="10.0" friction="0.1"/>
  </joint>
  <link name="link_5">
    <inertial>
      <origin rpy="0 0 0" xyz="0.0 -0.029824 0.076267"/>
      <mass value="1.529239"/>
      <inertia ixx="0.008485" ixy="0.0" ixz="0.0" iyy="0.007136" iyz="0.002806" izz="0.003848"/>
    </inertial>
    <visual>
      <origin rpy="0 0 0" xyz="0.0 0.0 -0.9475"/>
      <geometry>
        <mesh filename="package://lbr_description/meshes/iiwa7/visual/link_5.dae"/>
      </geometry>
    </visual>
    <collision>
      <origin rpy="0 0 0" xyz="0.0 0.0 -0.9475"/>
      <geometry>
        <mesh filename="package://lbr_description/meshes/iiwa7/collision/link_5.stl"/>
      </geometry>
    </collision>
  </link>
  <joint name="A6" type="revolute">
    <origin rpy="0 0 0" xyz="0.0 -0.0707 0.1925"/>
    <parent link="link_5"/>
    <child link="link_6"/>
    <axis xyz="0.0 1.0 0.0"/>
    <limit effort="200" lower="-2.0943951023931953" upper="2.0943951023931953" velocity="3.141592653589793"/>
    <dynamics damping="10.0" friction="0.1"/>
  </joint>
  <link name="link_6">
    <inertial>
      <origin rpy="0 0 0" xyz="0.0 0.07102 0.00495"/>
      <mass value="2.403626"/>
      <inertia ixx="0.007067" ixy="0.0" ixz="0.0" iyy="0.006804" iyz="0.000311" izz="0.004629"/>
    </inertial>
    <visual>
      <origin rpy="0 0 0" xyz="0.0 0.0707 -1.14"/>
      <geometry>
        <mesh filename="package://lbr_description/meshes/iiwa7/visual/link_6.dae"/>
      </geometry>
    </visual>
    <collision>
      <origin rpy="0 0 0" xyz="0.0 0.0707 -1.14"/>
      <geometry>
        <mesh filename="package://lbr_description/meshes/iiwa7/collision/link_6.stl"/>
      </geometry>
    </collision>
  </link>
  <joint name="A7" type="revolute">
    <origin rpy="0 0 0" xyz="0.0 0.0707 0.091"/>
    <parent link="link_6"/>
    <child link="link_7"/>
    <axis xyz="0.0 0.0 1.0"/>
    <limit effort="200" lower="-3.0543261909900763" upper="3.0543261909900763" velocity="3.141592653589793"/>
    <dynamics damping="10.0" friction="0.1"/>
  </joint>
  <link name="link_7">
    <inertial>
      <origin rpy="0 0 0" xyz="3.0000e-06 -2.0000e-06 1.3782e-02"/>
      <mass value="0.259474"/>
      <inertia ixx="0.000171" ixy="0.0" ixz="0.0" iyy="0.000171" iyz="0.0" izz="0.000299"/>
    </inertial>
    <visual>
      <origin rpy="0 0 0" xyz="0.0 0.0 -1.231"/>
      <geometry>
        <mesh filename="package://lbr_description/meshes/iiwa7/visual/link_7.dae"/>
      </geometry>
    </visual>
    <collision>
      <origin rpy="0 0 0" xyz="0.0 0.0 -1.231"/>
      <geometry>
        <mesh filename="package://lbr_description/meshes/iiwa7/collision/link_7.stl"/>
      </geometry>
    </collision>
  </link>
  <!-- <joint name="joint_ee" type="fixed">
            <parent link="link_7" />
            <child link="link_ee" />
            <origin xyz="0 0 0.035" rpy="0 0 0" />
        </joint>

        <link name="link_ee">
        </link> -->
  <!-- End Effector -->
  <link name="link_ee">
    <inertial>
      <origin rpy="1.57 0 1.57" xyz="0 0 0.08524"/>
      <mass value="0.55"/>
      <inertia ixx="0.0001" ixy="0.0" ixz="0.0" iyy="0.0001" iyz="0.0" izz="0.0001"/>
    </inertial>
    <visual>
      <origin rpy="1.57 0 1.57" xyz="-0.0925 0 0.035"/>
      <geometry>
        <mesh filename="package://lbr_description/meshes/iiwa7/collision/robotiq_gripper.stl" scale="0.001 0.001 0.001"/>
      </geometry>
    </visual>
    <collision>
      <origin rpy="1.57 0 1.57" xyz="-0.0925 0 0.035"/>
      <geometry>
        <mesh filename="package://lbr_description/meshes/iiwa7/collision/robotiq_gripper.stl" scale="0.001 0.001 0.001"/>
      </geometry>
    </collision>
  </link>
  <joint name="joint_ee" type="fixed">
    <parent link="link_7"/>
    <child link="link_ee"/>
    <origin rpy="0 0 0" xyz="0 0 0"/>
  </joint>
  <link name="link_tcp"/>
  <joint name="joint_tcp" type="fixed">
    <parent link="link_ee"/>
    <child link="link_tcp"/>
    <origin rpy="0 0 0" xyz="-0.00022 0.00163 0.17048"/>
  </joint>

  <!-- Robot 2 -->
  <material name="Black">
    <color rgba="0.0 0.0 0.0 1.0"/>
  </material>
  <material name="Blue">
    <color rgba="0.0 0.0 0.8 1.0"/>
  </material>
  <material name="Green">
    <color rgba="0.0 0.8 0.0 1.0"/>
  </material>
  <material name="Grey">
    <color rgba="0.4 0.4 0.4 1.0"/>
  </material>
  <material name="Orange">
    <color rgba="1.0 0.4235294117647059 0.0392156862745098 1.0"/>
  </material>
  <material name="Brown">
    <color rgba="0.8705882352941177 0.8117647058823529 0.7647058823529411 1.0"/>
  </material>
  <material name="Red">
    <color rgba="0.8 0.0 0.0 1.0"/>
  </material>
  <material name="White">
    <color rgba="1.0 1.0 1.0 1.0"/>
  </material>
  <joint name="aworld_joint" type="fixed">
    <parent link="world"/>
    <child link="alink_0"/>
    <!-- <origin xyz="0.55 -0.4 -0.25" rpy="0 0 0.783"/> -->
    <!-- <origin xyz="0.55 -0.4 -0.35" rpy="0 0 0.783"/> -->
    <origin rpy="0 0 0" xyz="0.3 0 0"/>
    <!-- <origin xyz="0.6 -0.5 -0.299" rpy="0 0 0.783"/> -->
  </joint>
  <link name="alink_0">
    <inertial>
      <origin rpy="0 0 0" xyz="-0.1 0 0.07"/>
      <mass value="4.855658"/>
      <inertia ixx="0.05" ixy="0" ixz="0" iyy="0.06" iyz="0" izz="0.03"/>
    </inertial>
    <visual>
      <origin rpy="0 0 0" xyz="0 0 0"/>
      <geometry>
        <mesh filename="package://iiwa7_description/meshes/iiwa7/visual/link_0.stl"/>
      </geometry>
      <material name="Grey"/>
    </visual>
    <collision>
      <origin rpy="0 0 0" xyz="0 0 0"/>
      <geometry>
        <mesh filename="package://iiwa7_description/meshes/iiwa7/collision/link_0.stl"/>
      </geometry>
      <material name="Grey"/>
    </collision>
  </link>
  <joint name="aA1" type="revolute">
    <origin rpy="0 0 0" xyz="0.0 0.0 0.15"/>
    <parent link="alink_0"/>
    <child link="alink_1"/>
    <axis xyz="0.0 0.0 1.0"/>
    <limit effort="200" lower="-2.9670597283903604" upper="2.9670597283903604" velocity="1.710422666954443"/>
    <dynamics damping="10.0" friction="0.1"/>
  </joint>
  <link name="alink_1">
    <inertial>
      <origin rpy="0 0 0" xyz="0.0 -0.034819 0.123299"/>
      <mass value="3.394011"/>
      <inertia ixx="0.021383" ixy="0.0" ixz="0.0" iyy="0.020403" iyz="0.003797" izz="0.007563"/>
    </inertial>
    <visual>
      <origin rpy="0 0 0" xyz="0.0 0.0 0.0075"/>
      <geometry>
        <mesh filename="package://iiwa7_description/meshes/iiwa7/visual/link_1.stl"/>
      </geometry>
      <material name="Orange"/>
    </visual>
    <collision>
      <origin rpy="0 0 0" xyz="0.0 0.0 0.0075"/>
      <geometry>
        <mesh filename="package://iiwa7_description/meshes/iiwa7/collision/link_1.stl"/>
      </geometry>
      <material name="Orange"/>
    </collision>
  </link>
  <joint name="aA2" type="revolute">
    <origin rpy="1.5707963267948966   0 3.141592653589793" xyz="0.0 0.0 0.19"/>
    <parent link="alink_1"/>
    <child link="alink_2"/>
    <axis xyz="0.0 0.0 1.0"/>
    <limit effort="200" lower="-2.0943951023931953" upper="2.0943951023931953" velocity="1.710422666954443"/>
    <dynamics damping="10.0" friction="0.1"/>
  </joint>
  <link name="alink_2">
    <inertial>
      <origin rpy="0 0 0" xyz="0.0 0.039793 0.086944"/>
      <mass value="4.031991"/>
      <inertia ixx="0.031697" ixy="0.0" ixz="0.0" iyy="0.03008" iyz="0.005889" izz="0.009666"/>
    </inertial>
    <visual>
      <origin rpy="0 0 0" xyz="0.0 0.0 0.0"/>
      <geometry>
        <mesh filename="package://iiwa7_description/meshes/iiwa7/visual/link_2.stl"/>
      </geometry>
      <material name="Orange"/>
    </visual>
    <collision>
      <origin rpy="0 0 0" xyz="0.0 0.0 0.0"/>
      <geometry>
        <mesh filename="package://iiwa7_description/meshes/iiwa7/collision/link_2.stl"/>
      </geometry>
      <material name="Orange"/>
    </collision>
  </link>
  <joint name="aA3" type="revolute">
    <origin rpy="1.5707963267948966 0 3.141592653589793" xyz="0.0 0.21 0.0"/>
    <parent link="alink_2"/>
    <child link="alink_3"/>
    <axis xyz="0.0 0.0 1.0"/>
    <limit effort="200" lower="-2.9670597283903604" upper="2.9670597283903604" velocity="1.7453292519943295"/>
    <dynamics damping="10.0" friction="0.1"/>
  </joint>
  <link name="alink_3">
    <inertial>
      <origin rpy="0 0 0" xyz="0.0 0.03 0.13"/>
      <mass value="3.394011"/>
      <inertia ixx="0.021383" ixy="0.0" ixz="0.0" iyy="0.020403" iyz="-0.003797" izz="0.007563"/>
    </inertial>
    <visual>
      <origin rpy="0 0 0" xyz="0.0 0.0 -0.026"/>
      <geometry>
        <mesh filename="package://iiwa7_description/meshes/iiwa7/visual/link_3.stl"/>
      </geometry>
      <material name="Orange"/>
    </visual>
    <collision>
      <origin rpy="0 0 0" xyz="0.0 0.0 -0.026"/>
      <geometry>
        <mesh filename="package://iiwa7_description/meshes/iiwa7/collision/link_3.stl"/>
      </geometry>
      <material name="Orange"/>
    </collision>
  </link>
  <joint name="aA4" type="revolute">
    <origin rpy="1.5707963267948966 0 0" xyz="0.0 0.0 0.19"/>
    <parent link="alink_3"/>
    <child link="alink_4"/>
    <axis xyz="0.0 0.0 1.0"/>
    <limit effort="200" lower="-2.0943951023931953" upper="2.0943951023931953" velocity="2.2689280275926285"/>
    <dynamics damping="10.0" friction="0.1"/>
  </joint>
  <link name="alink_4">
    <inertial>
      <origin rpy="0 0 0" xyz="0 0.067 0.034"/>
      <mass value="4.031989"/>
      <inertia ixx="0.031695" ixy="0.0" ixz="0.0" iyy="0.030079" iyz="-0.005889" izz="0.009665"/>
    </inertial>
    <visual>
      <origin rpy="0 0 0" xyz="0 0 0"/>
      <geometry>
        <mesh filename="package://iiwa7_description/meshes/iiwa7/visual/link_4.stl"/>
      </geometry>
      <material name="Orange"/>
    </visual>
    <collision>
      <origin rpy="0 0 0" xyz="0 0 0"/>
      <geometry>
        <mesh filename="package://iiwa7_description/meshes/iiwa7/collision/link_4.stl"/>
      </geometry>
      <material name="Orange"/>
    </collision>
  </link>
  <joint name="aA5" type="revolute">
    <origin rpy="-1.5707963267948966 3.141592653589793 0" xyz="0.0 0.21 0.0"/>
    <parent link="alink_4"/>
    <child link="alink_5"/>
    <axis xyz="0.0 0.0 1.0"/>
    <limit effort="200" lower="-2.9670597283903604" upper="2.9670597283903604" velocity="2.443460952792061"/>
    <dynamics damping="10.0" friction="0.1"/>
  </joint>
  <link name="alink_5">
    <inertial>
      <origin rpy="0 0 0" xyz="0.0001 0.021 0.076"/>
      <mass value="1.529239"/>
      <inertia ixx="0.008485" ixy="0.0" ixz="0.0" iyy="0.007136" iyz="0.002806" izz="0.003848"/>
    </inertial>
    <visual>
      <origin rpy="0 0 0" xyz="0 0 -0.026"/>
      <geometry>
        <mesh filename="package://iiwa7_description/meshes/iiwa7/visual/link_5.stl"/>
      </geometry>
      <material name="Orange"/>
    </visual>
    <collision>
      <origin rpy="0 0 0" xyz="0 0 -0.026"/>
      <geometry>
        <mesh filename="package://iiwa7_description/meshes/iiwa7/collision/link_5.stl"/>
      </geometry>
      <material name="Orange"/>
    </collision>
  </link>
  <joint name="aA6" type="revolute">
    <origin rpy="1.5707963267948966 0 0" xyz="0 0.06070 0.19"/>
    <parent link="alink_5"/>
    <child link="alink_6"/>
    <axis xyz="0.0 0.0 1.0"/>
    <limit effort="200" lower="-2.0943951023931953" upper="2.0943951023931953" velocity="3.141592653589793"/>
    <dynamics damping="10.0" friction="0.1"/>
  </joint>
  <link name="alink_6">
    <inertial>
      <origin rpy="0 0 0" xyz="0 0.0006 0.0004"/>
      <mass value="2.403626"/>
      <inertia ixx="0.007067" ixy="0.0" ixz="0.0" iyy="0.006804" iyz="0.000311" izz="0.004629"/>
    </inertial>
    <visual>
      <origin rpy="0 0 0" xyz="0 0 0"/>
      <geometry>
        <mesh filename="package://iiwa7_description/meshes/iiwa7/visual/link_6.stl"/>
      </geometry>
      <material name="Orange"/>
    </visual>
    <collision>
      <origin rpy="0 0 0" xyz="0 0 0"/>
      <geometry>
        <mesh filename="package://iiwa7_description/meshes/iiwa7/collision/link_6.stl"/>
      </geometry>
      <material name="Orange"/>
    </collision>
  </link>
  <joint name="aA7" type="revolute">
    <origin rpy="-1.5707963267948966 3.141592653589793 0" xyz="0 0.081 0.06070"/>
    <parent link="alink_6"/>
    <child link="alink_7"/>
    <axis xyz="0.0 0.0 1.0"/>
    <limit effort="200" lower="-3.0543261909900763" upper="3.0543261909900763" velocity="3.141592653589793"/>
    <dynamics damping="10.0" friction="0.1"/>
  </joint>
  <link name="alink_7">
    <inertial>
      <origin rpy="0 0 0" xyz="0 0 0.02"/>
      <mass value="0.259474"/>
      <inertia ixx="0.000171" ixy="0.0" ixz="0.0" iyy="0.000171" iyz="0.0" izz="0.000299"/>
    </inertial>
    <visual>
      <origin rpy="0 0 0" xyz="0 0 -0.0005"/>
      <geometry>
        <mesh filename="package://iiwa7_description/meshes/iiwa7/visual/link_7.stl"/>
      </geometry>
      <material name="Grey"/>
    </visual>
    <collision>
      <origin rpy="0 0 0" xyz="0 0 -0.0005"/>
      <geometry>
        <mesh filename="package://iiwa7_description/meshes/iiwa7/collision/link_7.stl"/>
      </geometry>
      <material name="Grey"/>
    </collision>
  </link>
  <!-- <joint name="joint_ee" type="fixed">
            <parent link="link_7" />
            <child link="link_ee" />
            <origin xyz="0 0 0.035" rpy="0 0 0" />
        </joint>

        <link name="link_ee">
        </link> -->
  <!-- End Effector -->
  <link name="alink_ee">
    <inertial>
      <origin rpy="1.57 0 1.57" xyz="0 0 0.08524"/>
      <mass value="0.55"/>
      <inertia ixx="0.0001" ixy="0.0" ixz="0.0" iyy="0.0001" iyz="0.0" izz="0.0001"/>
    </inertial>
    <visual>
      <origin rpy="1.57 0 1.57" xyz="-0.0925 0 0.045"/>
      <geometry>
        <mesh filename="package://lbr_description/meshes/iiwa7/collision/robotiq_gripper.stl" scale="0.001 0.001 0.001"/>
      </geometry>
      <!-- <material name="Black"/> -->
    </visual>
    <collision>
      <origin rpy="1.57 0 1.57" xyz="-0.0925 0 0.045"/>
      <geometry>
        <mesh filename="package://lbr_description/meshes/iiwa7/collision/robotiq_gripper.stl" scale="0.001 0.001 0.001"/>
      </geometry>
      <!-- <material name="Black"/> -->
    </collision>
  </link>
  <joint name="ajoint_ee" type="fixed">
    <parent link="alink_7"/>
    <child link="alink_ee"/>
    <origin rpy="0 0 0" xyz="0 0 0"/>
  </joint>
  <link name="alink_tcp"/>
  <joint name="ajoint_tcp" type="fixed">
    <parent link="alink_ee"/>
    <child link="alink_tcp"/>
    <origin rpy="0 0 0" xyz="-0.00022 0.00163 0.17048"/>
  </joint>
</robot>
