<?xml version="1.0" ?>
<!-- =================================================================================== -->
<!-- |    This document was autogenerated by xacro from /home/cam/multi_iiwa_ws/src/lbr_fri_ros2_stack/lbr_description/urdf/dual_iiwa7/dual_iiwa7_mod.xacro | -->
<!-- |    EDITING THIS FILE BY HAND IS NOT RECOMMENDED                                 | -->
<!-- =================================================================================== -->
<robot name="dual_iiwa7">
  <!-- Base link for the world -->
  <!-- <link name="world" /> -->
  <link name="world">
    <origin rpy="0 0 0" xyz="0 0 0"/>
  </link>

  <joint name="world_kuka_blue_joint" type="fixed">
    <origin rpy="0 0 0" xyz="0 0 0"/>
    <parent link="world"/>
    <child link="kuka_blue_link_0"/>
  </joint>
  <link name="kuka_blue_link_0">
    <inertial>
      <origin rpy="0 0 0" xyz="-0.012857 0.0 0.069964"/>
      <mass value="4.855658"/>
      <inertia ixx="0.017839" ixy="0.0" ixz="0.000781" iyy="0.022294" iyz="0.0" izz="0.021334"/>
    </inertial>
    <visual>
      <origin rpy="0 0 0" xyz="0 0 0"/>
      <geometry>
        <mesh filename="package://lbr_description/meshes/iiwa7/visual/link_0.dae"/>
      </geometry>
    </visual>
    <collision>
      <origin rpy="0 0 0" xyz="0 0 0"/>
      <geometry>
        <mesh filename="package://lbr_description/meshes/iiwa7/collision/link_0.stl"/>
      </geometry>
    </collision>
  </link>
  <joint name="kuka_blue_A1" type="revolute">
    <origin rpy="0 0 0" xyz="0.0 0.0 0.1475"/>
    <parent link="kuka_blue_link_0"/>
    <child link="kuka_blue_link_1"/>
    <axis xyz="0.0 0.0 1.0"/>
    <limit effort="200" lower="-2.9670597283903604" upper="2.9670597283903604" velocity="1.710422666954443"/>
    <dynamics damping="10.0" friction="0.1"/>
  </joint>
  <link name="kuka_blue_link_1">
    <inertial>
      <origin rpy="0 0 0" xyz="0.0 -0.034819 0.123299"/>
      <mass value="3.394011"/>
      <inertia ixx="0.021383" ixy="0.0" ixz="0.0" iyy="0.020403" iyz="0.003797" izz="0.007563"/>
    </inertial>
    <visual>
      <origin rpy="0 0 0" xyz="0.0 0.0 -0.1475"/>
      <geometry>
        <mesh filename="package://lbr_description/meshes/iiwa7/visual/link_1.dae"/>
      </geometry>
    </visual>
    <collision>
      <origin rpy="0 0 0" xyz="0.0 0.0 -0.1475"/>
      <geometry>
        <mesh filename="package://lbr_description/meshes/iiwa7/collision/link_1.stl"/>
      </geometry>
    </collision>
  </link>
  <joint name="kuka_blue_A2" type="revolute">
    <origin rpy="0 0 0" xyz="0.0 -0.0105 0.1925"/>
    <parent link="kuka_blue_link_1"/>
    <child link="kuka_blue_link_2"/>
    <axis xyz="0.0 1.0 0.0"/>
    <limit effort="200" lower="-2.0943951023931953" upper="2.0943951023931953" velocity="1.710422666954443"/>
    <dynamics damping="10.0" friction="0.1"/>
  </joint>
  <link name="kuka_blue_link_2">
    <inertial>
      <origin rpy="0 0 0" xyz="0.0 0.039793 0.086944"/>
      <mass value="4.031991"/>
      <inertia ixx="0.031697" ixy="0.0" ixz="0.0" iyy="0.03008" iyz="0.005889" izz="0.009666"/>
    </inertial>
    <visual>
      <origin rpy="0 0 0" xyz="0.0 0.0105 -0.34"/>
      <geometry>
        <mesh filename="package://lbr_description/meshes/iiwa7/visual/link_2.dae"/>
      </geometry>
    </visual>
    <collision>
      <origin rpy="0 0 0" xyz="0.0 0.0105 -0.34"/>
      <geometry>
        <mesh filename="package://lbr_description/meshes/iiwa7/collision/link_2.stl"/>
      </geometry>
    </collision>
  </link>
  <joint name="kuka_blue_A3" type="revolute">
    <origin rpy="0 0 0" xyz="0.0 0.0105 0.2075"/>
    <parent link="kuka_blue_link_2"/>
    <child link="kuka_blue_link_3"/>
    <axis xyz="0.0 0.0 1.0"/>
    <limit effort="200" lower="-2.9670597283903604" upper="2.9670597283903604" velocity="1.7453292519943295"/>
    <dynamics damping="10.0" friction="0.1"/>
  </joint>
  <link name="kuka_blue_link_3">
    <inertial>
      <origin rpy="0 0 0" xyz="0.0 0.034819 0.123299"/>
      <mass value="3.394011"/>
      <inertia ixx="0.021383" ixy="0.0" ixz="0.0" iyy="0.020403" iyz="-0.003797" izz="0.007563"/>
    </inertial>
    <visual>
      <origin rpy="0 0 0" xyz="0.0 0.0 -0.5475"/>
      <geometry>
        <mesh filename="package://lbr_description/meshes/iiwa7/visual/link_3.dae"/>
      </geometry>
    </visual>
    <collision>
      <origin rpy="0 0 0" xyz="0.0 0.0 -0.5475"/>
      <geometry>
        <mesh filename="package://lbr_description/meshes/iiwa7/collision/link_3.stl"/>
      </geometry>
    </collision>
  </link>
  <joint name="kuka_blue_A4" type="revolute">
    <origin rpy="0 0 0" xyz="0.0 0.0105 0.1925"/>
    <parent link="kuka_blue_link_3"/>
    <child link="kuka_blue_link_4"/>
    <axis xyz="0.0 -1.0 0.0"/>
    <limit effort="200" lower="-2.0943951023931953" upper="2.0943951023931953" velocity="2.2689280275926285"/>
    <dynamics damping="10.0" friction="0.1"/>
  </joint>
  <link name="kuka_blue_link_4">
    <inertial>
      <origin rpy="0 0 0" xyz="0.0 -0.039793 0.086944"/>
      <mass value="4.031989"/>
      <inertia ixx="0.031695" ixy="0.0" ixz="0.0" iyy="0.030079" iyz="-0.005889" izz="0.009665"/>
    </inertial>
    <visual>
      <origin rpy="0 0 0" xyz="0.0 -0.0105 -0.74"/>
      <geometry>
        <mesh filename="package://lbr_description/meshes/iiwa7/visual/link_4.dae"/>
      </geometry>
    </visual>
    <collision>
      <origin rpy="0 0 0" xyz="0.0 -0.0105 -0.74"/>
      <geometry>
        <mesh filename="package://lbr_description/meshes/iiwa7/collision/link_4.stl"/>
      </geometry>
    </collision>
  </link>
  <joint name="kuka_blue_A5" type="revolute">
    <origin rpy="0 0 0" xyz="0.0 -0.0105 0.2075"/>
    <parent link="kuka_blue_link_4"/>
    <child link="kuka_blue_link_5"/>
    <axis xyz="0.0 0.0 1.0"/>
    <limit effort="200" lower="-2.9670597283903604" upper="2.9670597283903604" velocity="2.443460952792061"/>
    <dynamics damping="10.0" friction="0.1"/>
  </joint>
  <link name="kuka_blue_link_5">
    <inertial>
      <origin rpy="0 0 0" xyz="0.0 -0.029824 0.076267"/>
      <mass value="1.529239"/>
      <inertia ixx="0.008485" ixy="0.0" ixz="0.0" iyy="0.007136" iyz="0.002806" izz="0.003848"/>
    </inertial>
    <visual>
      <origin rpy="0 0 0" xyz="0.0 0.0 -0.9475"/>
      <geometry>
        <mesh filename="package://lbr_description/meshes/iiwa7/visual/link_5.dae"/>
      </geometry>
    </visual>
    <collision>
      <origin rpy="0 0 0" xyz="0.0 0.0 -0.9475"/>
      <geometry>
        <mesh filename="package://lbr_description/meshes/iiwa7/collision/link_5.stl"/>
      </geometry>
    </collision>
  </link>
  <joint name="kuka_blue_A6" type="revolute">
    <origin rpy="0 0 0" xyz="0.0 -0.0707 0.1925"/>
    <parent link="kuka_blue_link_5"/>
    <child link="kuka_blue_link_6"/>
    <axis xyz="0.0 1.0 0.0"/>
    <limit effort="200" lower="-2.0943951023931953" upper="2.0943951023931953" velocity="3.141592653589793"/>
    <dynamics damping="10.0" friction="0.1"/>
  </joint>
  <link name="kuka_blue_link_6">
    <inertial>
      <origin rpy="0 0 0" xyz="0.0 0.07102 0.00495"/>
      <mass value="2.403626"/>
      <inertia ixx="0.007067" ixy="0.0" ixz="0.0" iyy="0.006804" iyz="0.000311" izz="0.004629"/>
    </inertial>
    <visual>
      <origin rpy="0 0 0" xyz="0.0 0.0707 -1.14"/>
      <geometry>
        <mesh filename="package://lbr_description/meshes/iiwa7/visual/link_6.dae"/>
      </geometry>
    </visual>
    <collision>
      <origin rpy="0 0 0" xyz="0.0 0.0707 -1.14"/>
      <geometry>
        <mesh filename="package://lbr_description/meshes/iiwa7/collision/link_6.stl"/>
      </geometry>
    </collision>
  </link>
  <joint name="kuka_blue_A7" type="revolute">
    <origin rpy="0 0 0" xyz="0.0 0.0707 0.091"/>
    <parent link="kuka_blue_link_6"/>
    <child link="kuka_blue_link_7"/>
    <axis xyz="0.0 0.0 1.0"/>
    <limit effort="200" lower="-3.0543261909900763" upper="3.0543261909900763" velocity="3.141592653589793"/>
    <dynamics damping="10.0" friction="0.1"/>
  </joint>
  <link name="kuka_blue_link_7">
    <inertial>
      <origin rpy="0 0 0" xyz="3.0000e-06 -2.0000e-06 1.3782e-02"/>
      <mass value="0.259474"/>
      <inertia ixx="0.000171" ixy="0.0" ixz="0.0" iyy="0.000171" iyz="0.0" izz="0.000299"/>
    </inertial>
    <visual>
      <origin rpy="0 0 0" xyz="0.0 0.0 -1.231"/>
      <geometry>
        <mesh filename="package://lbr_description/meshes/iiwa7/visual/link_7.dae"/>
      </geometry>
    </visual>
    <collision>
      <origin rpy="0 0 0" xyz="0.0 0.0 -1.231"/>
      <geometry>
        <mesh filename="package://lbr_description/meshes/iiwa7/collision/link_7.stl"/>
      </geometry>
    </collision>
  </link>
  <joint name="kuka_blue_joint_ee" type="fixed">
    <parent link="kuka_blue_link_7"/>
    <child link="kuka_blue_link_ee"/>
    <origin rpy="0 0 0" xyz="0 0 0.035"/>
  </joint>
  <link name="kuka_blue_link_ee">
    <inertial>
      <origin rpy="0 0 0" xyz="0 0 0"/>
      <mass value="1.3"/>
      <inertia ixx="0.0001" ixy="0.0" ixz="0.0" iyy="0.0001" iyz="0.0" izz="0.0001"/>
    </inertial>
    <visual>
      <origin rpy="1.5708 0 0" xyz="0.0 0.0 0.035"/>
      <geometry>
        <mesh filename="package://lbr_description/meshes/iiwa7/visual/gripper_collision.dae"/>
      </geometry>
    </visual>
    <collision>
      <origin rpy="1.5708 0 0" xyz="0.0 0.0 0.035"/>
      <geometry>
        <mesh filename="package://lbr_description/meshes/iiwa7/collision/compressed_gripper.stl"/>
      </geometry>
    </collision>
  </link>
  <joint name="kuka_blue_joint_tcp" type="fixed">
    <parent link="kuka_blue_link_ee"/>
    <child link="kuka_blue_link_tcp"/>
    <origin rpy="0 0 0" xyz="-0.0002 0.0016 0.1705"/>
  </joint>
  <link name="kuka_blue_link_tcp">
        </link>

  <joint name="world_kuka_green_joint" type="fixed">
    <origin rpy="0 0 0" xyz="1 1 0"/>
    <parent link="world"/>
    <child link="kuka_green_link_0"/>
  </joint>
  <link name="kuka_green_link_0">
    <inertial>
      <origin rpy="0 0 0" xyz="-0.012857 0.0 0.069964"/>
      <mass value="4.855658"/>
      <inertia ixx="0.017839" ixy="0.0" ixz="0.000781" iyy="0.022294" iyz="0.0" izz="0.021334"/>
    </inertial>
    <visual>
      <origin rpy="0 0 0" xyz="0 0 0"/>
      <geometry>
        <mesh filename="package://lbr_description/meshes/iiwa7/visual/link_0.dae"/>
      </geometry>
    </visual>
    <collision>
      <origin rpy="0 0 0" xyz="0 0 0"/>
      <geometry>
        <mesh filename="package://lbr_description/meshes/iiwa7/collision/link_0.stl"/>
      </geometry>
    </collision>
  </link>
  <joint name="kuka_green_A1" type="revolute">
    <origin rpy="0 0 0" xyz="0.0 0.0 0.1475"/>
    <parent link="kuka_green_link_0"/>
    <child link="kuka_green_link_1"/>
    <axis xyz="0.0 0.0 1.0"/>
    <limit effort="200" lower="-2.9670597283903604" upper="2.9670597283903604" velocity="1.710422666954443"/>
    <dynamics damping="10.0" friction="0.1"/>
  </joint>
  <link name="kuka_green_link_1">
    <inertial>
      <origin rpy="0 0 0" xyz="0.0 -0.034819 0.123299"/>
      <mass value="3.394011"/>
      <inertia ixx="0.021383" ixy="0.0" ixz="0.0" iyy="0.020403" iyz="0.003797" izz="0.007563"/>
    </inertial>
    <visual>
      <origin rpy="0 0 0" xyz="0.0 0.0 -0.1475"/>
      <geometry>
        <mesh filename="package://lbr_description/meshes/iiwa7/visual/link_1.dae"/>
      </geometry>
    </visual>
    <collision>
      <origin rpy="0 0 0" xyz="0.0 0.0 -0.1475"/>
      <geometry>
        <mesh filename="package://lbr_description/meshes/iiwa7/collision/link_1.stl"/>
      </geometry>
    </collision>
  </link>
  <joint name="kuka_green_A2" type="revolute">
    <origin rpy="0 0 0" xyz="0.0 -0.0105 0.1925"/>
    <parent link="kuka_green_link_1"/>
    <child link="kuka_green_link_2"/>
    <axis xyz="0.0 1.0 0.0"/>
    <limit effort="200" lower="-2.0943951023931953" upper="2.0943951023931953" velocity="1.710422666954443"/>
    <dynamics damping="10.0" friction="0.1"/>
  </joint>
  <link name="kuka_green_link_2">
    <inertial>
      <origin rpy="0 0 0" xyz="0.0 0.039793 0.086944"/>
      <mass value="4.031991"/>
      <inertia ixx="0.031697" ixy="0.0" ixz="0.0" iyy="0.03008" iyz="0.005889" izz="0.009666"/>
    </inertial>
    <visual>
      <origin rpy="0 0 0" xyz="0.0 0.0105 -0.34"/>
      <geometry>
        <mesh filename="package://lbr_description/meshes/iiwa7/visual/link_2.dae"/>
      </geometry>
    </visual>
    <collision>
      <origin rpy="0 0 0" xyz="0.0 0.0105 -0.34"/>
      <geometry>
        <mesh filename="package://lbr_description/meshes/iiwa7/collision/link_2.stl"/>
      </geometry>
    </collision>
  </link>
  <joint name="kuka_green_A3" type="revolute">
    <origin rpy="0 0 0" xyz="0.0 0.0105 0.2075"/>
    <parent link="kuka_green_link_2"/>
    <child link="kuka_green_link_3"/>
    <axis xyz="0.0 0.0 1.0"/>
    <limit effort="200" lower="-2.9670597283903604" upper="2.9670597283903604" velocity="1.7453292519943295"/>
    <dynamics damping="10.0" friction="0.1"/>
  </joint>
  <link name="kuka_green_link_3">
    <inertial>
      <origin rpy="0 0 0" xyz="0.0 0.034819 0.123299"/>
      <mass value="3.394011"/>
      <inertia ixx="0.021383" ixy="0.0" ixz="0.0" iyy="0.020403" iyz="-0.003797" izz="0.007563"/>
    </inertial>
    <visual>
      <origin rpy="0 0 0" xyz="0.0 0.0 -0.5475"/>
      <geometry>
        <mesh filename="package://lbr_description/meshes/iiwa7/visual/link_3.dae"/>
      </geometry>
    </visual>
    <collision>
      <origin rpy="0 0 0" xyz="0.0 0.0 -0.5475"/>
      <geometry>
        <mesh filename="package://lbr_description/meshes/iiwa7/collision/link_3.stl"/>
      </geometry>
    </collision>
  </link>
  <joint name="kuka_green_A4" type="revolute">
    <origin rpy="0 0 0" xyz="0.0 0.0105 0.1925"/>
    <parent link="kuka_green_link_3"/>
    <child link="kuka_green_link_4"/>
    <axis xyz="0.0 -1.0 0.0"/>
    <limit effort="200" lower="-2.0943951023931953" upper="2.0943951023931953" velocity="2.2689280275926285"/>
    <dynamics damping="10.0" friction="0.1"/>
  </joint>
  <link name="kuka_green_link_4">
    <inertial>
      <origin rpy="0 0 0" xyz="0.0 -0.039793 0.086944"/>
      <mass value="4.031989"/>
      <inertia ixx="0.031695" ixy="0.0" ixz="0.0" iyy="0.030079" iyz="-0.005889" izz="0.009665"/>
    </inertial>
    <visual>
      <origin rpy="0 0 0" xyz="0.0 -0.0105 -0.74"/>
      <geometry>
        <mesh filename="package://lbr_description/meshes/iiwa7/visual/link_4.dae"/>
      </geometry>
    </visual>
    <collision>
      <origin rpy="0 0 0" xyz="0.0 -0.0105 -0.74"/>
      <geometry>
        <mesh filename="package://lbr_description/meshes/iiwa7/collision/link_4.stl"/>
      </geometry>
    </collision>
  </link>
  <joint name="kuka_green_A5" type="revolute">
    <origin rpy="0 0 0" xyz="0.0 -0.0105 0.2075"/>
    <parent link="kuka_green_link_4"/>
    <child link="kuka_green_link_5"/>
    <axis xyz="0.0 0.0 1.0"/>
    <limit effort="200" lower="-2.9670597283903604" upper="2.9670597283903604" velocity="2.443460952792061"/>
    <dynamics damping="10.0" friction="0.1"/>
  </joint>
  <link name="kuka_green_link_5">
    <inertial>
      <origin rpy="0 0 0" xyz="0.0 -0.029824 0.076267"/>
      <mass value="1.529239"/>
      <inertia ixx="0.008485" ixy="0.0" ixz="0.0" iyy="0.007136" iyz="0.002806" izz="0.003848"/>
    </inertial>
    <visual>
      <origin rpy="0 0 0" xyz="0.0 0.0 -0.9475"/>
      <geometry>
        <mesh filename="package://lbr_description/meshes/iiwa7/visual/link_5.dae"/>
      </geometry>
    </visual>
    <collision>
      <origin rpy="0 0 0" xyz="0.0 0.0 -0.9475"/>
      <geometry>
        <mesh filename="package://lbr_description/meshes/iiwa7/collision/link_5.stl"/>
      </geometry>
    </collision>
  </link>
  <joint name="kuka_green_A6" type="revolute">
    <origin rpy="0 0 0" xyz="0.0 -0.0707 0.1925"/>
    <parent link="kuka_green_link_5"/>
    <child link="kuka_green_link_6"/>
    <axis xyz="0.0 1.0 0.0"/>
    <limit effort="200" lower="-2.0943951023931953" upper="2.0943951023931953" velocity="3.141592653589793"/>
    <dynamics damping="10.0" friction="0.1"/>
  </joint>
  <link name="kuka_green_link_6">
    <inertial>
      <origin rpy="0 0 0" xyz="0.0 0.07102 0.00495"/>
      <mass value="2.403626"/>
      <inertia ixx="0.007067" ixy="0.0" ixz="0.0" iyy="0.006804" iyz="0.000311" izz="0.004629"/>
    </inertial>
    <visual>
      <origin rpy="0 0 0" xyz="0.0 0.0707 -1.14"/>
      <geometry>
        <mesh filename="package://lbr_description/meshes/iiwa7/visual/link_6.dae"/>
      </geometry>
    </visual>
    <collision>
      <origin rpy="0 0 0" xyz="0.0 0.0707 -1.14"/>
      <geometry>
        <mesh filename="package://lbr_description/meshes/iiwa7/collision/link_6.stl"/>
      </geometry>
    </collision>
  </link>
  <joint name="kuka_green_A7" type="revolute">
    <origin rpy="0 0 0" xyz="0.0 0.0707 0.091"/>
    <parent link="kuka_green_link_6"/>
    <child link="kuka_green_link_7"/>
    <axis xyz="0.0 0.0 1.0"/>
    <limit effort="200" lower="-3.0543261909900763" upper="3.0543261909900763" velocity="3.141592653589793"/>
    <dynamics damping="10.0" friction="0.1"/>
  </joint>
  <link name="kuka_green_link_7">
    <inertial>
      <origin rpy="0 0 0" xyz="3.0000e-06 -2.0000e-06 1.3782e-02"/>
      <mass value="0.259474"/>
      <inertia ixx="0.000171" ixy="0.0" ixz="0.0" iyy="0.000171" iyz="0.0" izz="0.000299"/>
    </inertial>
    <visual>
      <origin rpy="0 0 0" xyz="0.0 0.0 -1.231"/>
      <geometry>
        <mesh filename="package://lbr_description/meshes/iiwa7/visual/link_7.dae"/>
      </geometry>
    </visual>
    <collision>
      <origin rpy="0 0 0" xyz="0.0 0.0 -1.231"/>
      <geometry>
        <mesh filename="package://lbr_description/meshes/iiwa7/collision/link_7.stl"/>
      </geometry>
    </collision>
  </link>
  <joint name="kuka_green_joint_ee" type="fixed">
    <parent link="kuka_green_link_7"/>
    <child link="kuka_green_link_ee"/>
    <origin rpy="0 0 0" xyz="0 0 0.035"/>
  </joint>
  <link name="kuka_green_link_ee">
    <inertial>
      <origin rpy="0 0 0" xyz="0 0 0"/>
      <mass value="0.1"/>
      <inertia ixx="0.0001" ixy="0.0" ixz="0.0" iyy="0.0001" iyz="0.0" izz="0.0001"/>
    </inertial>
    <visual>
      <origin rpy="0 0 0" xyz="0.0 -0.022 0.035"/>
      <geometry>
        <mesh filename="package://lbr_description/meshes/iiwa7/visual/scooper_collision.dae"/>
      </geometry>
    </visual>
    <collision>
      <origin rpy="0 0 0" xyz="0.0 -0.022 0.035"/>
      <geometry>
        <mesh filename="package://lbr_description/meshes/iiwa7/collision/compressed_mesh_scooper.stl"/>
      </geometry>
    </collision>
  </link>
  <joint name="kuka_green_joint_tcp" type="fixed">
    <parent link="kuka_green_link_ee"/>
    <child link="kuka_green_link_tcp"/>
    <origin rpy="0 0 0" xyz="-0.0156 -0.0024 0.3386"/>
  </joint>
  <link name="kuka_green_link_tcp">
        </link>
</robot>
